<?xml version="1.0" ?>
<robot
  name="lmm_model">
  <link
    name="Trunk_Body">
    <inertial>
      <origin
        xyz="1.3281E-13 0.062281 0.001451"
        rpy="0 0 0" />
      <mass
        value="1.0729" />
      <inertia
        ixx="0.028402"
        ixy="2.0748E-19"
        ixz="3.2037E-18"
        iyy="0.00402"
        iyz="-2.8561E-05"
        izz="0.028936" />
    </inertial>
    <visual>
      <origin
        xyz="0 0 0"
        rpy="0 0 0" />
      <geometry>
        <mesh
          filename="package://lmm_model/meshes/Trunk_Body.STL" />
      </geometry>
      <material
        name="">
        <color
          rgba="0.89804 0.91765 0.92941 1" />
      </material>
    </visual>
    <collision>
      <origin
        xyz="0 0 0"
        rpy="0 0 0" />
      <geometry>
        <mesh
          filename="package://lmm_model/meshes/Trunk_Body.STL" />
      </geometry>
    </collision>
  </link>
  <link
    name="Leg_1_Link_1">
    <inertial>
      <origin
        xyz="-0.036469 0.00022501 0.0010278"
        rpy="0 0 0" />
      <mass
        value="0.12581" />
      <inertia
        ixx="6.0449E-05"
        ixy="1.6569E-06"
        ixz="-3.4003E-06"
        iyy="0.00019067"
        iyz="2.9093E-08"
        izz="0.00018671" />
    </inertial>
    <visual>
      <origin
        xyz="0 0 0"
        rpy="0 0 0" />
      <geometry>
        <mesh
          filename="package://lmm_model/meshes/Leg_1_Link_1.STL" />
      </geometry>
      <material
        name="">
        <color
          rgba="0.89804 0.91765 0.92941 1" />
      </material>
    </visual>
    <collision>
      <origin
        xyz="0 0 0"
        rpy="0 0 0" />
      <geometry>
        <mesh
          filename="package://lmm_model/meshes/Leg_1_Link_1.STL" />
      </geometry>
    </collision>
  </link>
  <joint
    name="joint_1_1"
    type="revolute">
    <origin
      xyz="-0.08 0.205 0.0155"
      rpy="0 0 0" />
    <parent
      link="Trunk_Body" />
    <child
      link="Leg_1_Link_1" />
    <axis
      xyz="0 0 1" />
    <limit
      lower="-1.5708"
      upper="1.5708"
      effort="3"
      velocity="5" />
  </joint>
  <link
    name="Leg_1_Link_2">
    <inertial>
      <origin
        xyz="-0.0525 0.0017906 -6.2897E-13"
        rpy="0 0 0" />
      <mass
        value="0.14442" />
      <inertia
        ixx="4.7435E-05"
        ixy="2.2284E-15"
        ixz="-3.5752E-15"
        iyy="0.00031196"
        iyz="-6.9138E-19"
        izz="0.00034589" />
    </inertial>
    <visual>
      <origin
        xyz="0 0 0"
        rpy="0 0 0" />
      <geometry>
        <mesh
          filename="package://lmm_model/meshes/Leg_1_Link_2.STL" />
      </geometry>
      <material
        name="">
        <color
          rgba="0.89804 0.91765 0.92941 1" />
      </material>
    </visual>
    <collision>
      <origin
        xyz="0 0 0"
        rpy="0 0 0" />
      <geometry>
        <mesh
          filename="package://lmm_model/meshes/Leg_1_Link_2.STL" />
      </geometry>
    </collision>
  </link>
  <joint
    name="joint_1_2"
    type="revolute">
    <origin
      xyz="-0.095 0 0"
      rpy="0 0 0" />
    <parent
      link="Leg_1_Link_1" />
    <child
      link="Leg_1_Link_2" />
    <axis
      xyz="0 1 0" />
    <limit
      lower="-1.5708"
      upper="1.5708"
      effort="3"
      velocity="5" />
  </joint>
  <link
    name="Leg_1_Link_3">
    <inertial>
      <origin
        xyz="-0.0308 1.926E-05 -3.6865E-13"
        rpy="0 0 0" />
      <mass
        value="0.055636" />
      <inertia
        ixx="2.6138E-05"
        ixy="-8.8979E-07"
        ixz="-8.3816E-16"
        iyy="7.6621E-05"
        iyz="5.6394E-15"
        izz="9.607E-05" />
    </inertial>
    <visual>
      <origin
        xyz="0 0 0"
        rpy="0 0 0" />
      <geometry>
        <mesh
          filename="package://lmm_model/meshes/Leg_1_Link_3.STL" />
      </geometry>
      <material
        name="">
        <color
          rgba="0.89804 0.91765 0.92941 1" />
      </material>
    </visual>
    <collision>
      <origin
        xyz="0 0 0"
        rpy="0 0 0" />
      <geometry>
        <mesh
          filename="package://lmm_model/meshes/Leg_1_Link_3.STL" />
      </geometry>
    </collision>
  </link>
  <joint
    name="joint_1_3"
    type="revolute">
    <origin
      xyz="-0.105 0 0"
      rpy="0 0 0" />
    <parent
      link="Leg_1_Link_2" />
    <child
      link="Leg_1_Link_3" />
    <axis
      xyz="0 1 0" />
    <limit
      lower="-3.1416"
      upper="0"
      effort="3"
      velocity="5" />
  </joint>
  <link
    name="Leg_2_Link_1">
    <inertial>
      <origin
        xyz="0.036469 0.00022501 0.0010278"
        rpy="0 0 0" />
      <mass
        value="0.12581" />
      <inertia
        ixx="6.0449E-05"
        ixy="-1.6569E-06"
        ixz="3.4003E-06"
        iyy="0.00019067"
        iyz="2.9093E-08"
        izz="0.00018671" />
    </inertial>
    <visual>
      <origin
        xyz="0 0 0"
        rpy="0 0 0" />
      <geometry>
        <mesh
          filename="package://lmm_model/meshes/Leg_2_Link_1.STL" />
      </geometry>
      <material
        name="">
        <color
          rgba="0.89804 0.91765 0.92941 1" />
      </material>
    </visual>
    <collision>
      <origin
        xyz="0 0 0"
        rpy="0 0 0" />
      <geometry>
        <mesh
          filename="package://lmm_model/meshes/Leg_2_Link_1.STL" />
      </geometry>
    </collision>
  </link>
  <joint
    name="joint_2_1"
    type="revolute">
    <origin
      xyz="0.08 0.205 0.0155"
      rpy="0 0 0" />
    <parent
      link="Trunk_Body" />
    <child
      link="Leg_2_Link_1" />
    <axis
      xyz="0 0 1" />
    <limit
      lower="-1.5708"
      upper="1.5708"
      effort="3"
      velocity="5" />
  </joint>
  <link
    name="Leg_2_Link_2">
    <inertial>
      <origin
        xyz="0.0525 0.0017906 6.2925E-13"
        rpy="0 0 0" />
      <mass
        value="0.14442" />
      <inertia
        ixx="4.7435E-05"
        ixy="2.2337E-15"
        ixz="-3.5775E-15"
        iyy="0.00031196"
        iyz="1.5359E-18"
        izz="0.00034589" />
    </inertial>
    <visual>
      <origin
        xyz="0 0 0"
        rpy="0 0 0" />
      <geometry>
        <mesh
          filename="package://lmm_model/meshes/Leg_2_Link_2.STL" />
      </geometry>
      <material
        name="">
        <color
          rgba="0.89804 0.91765 0.92941 1" />
      </material>
    </visual>
    <collision>
      <origin
        xyz="0 0 0"
        rpy="0 0 0" />
      <geometry>
        <mesh
          filename="package://lmm_model/meshes/Leg_2_Link_2.STL" />
      </geometry>
    </collision>
  </link>
  <joint
    name="joint_2_2"
    type="revolute">
    <origin
      xyz="0.095 0 0"
      rpy="0 0 0" />
    <parent
      link="Leg_2_Link_1" />
    <child
      link="Leg_2_Link_2" />
    <axis
      xyz="0 1 0" />
    <limit
      lower="-1.5708"
      upper="1.5708"
      effort="3"
      velocity="5" />
  </joint>
  <link
    name="Leg_2_Link_3">
    <inertial>
      <origin
        xyz="0.0308 1.926E-05 3.6887E-13"
        rpy="0 0 0" />
      <mass
        value="0.055636" />
      <inertia
        ixx="2.6138E-05"
        ixy="8.8979E-07"
        ixz="-8.3861E-16"
        iyy="7.6621E-05"
        iyz="-5.6389E-15"
        izz="9.607E-05" />
    </inertial>
    <visual>
      <origin
        xyz="0 0 0"
        rpy="0 0 0" />
      <geometry>
        <mesh
          filename="package://lmm_model/meshes/Leg_2_Link_3.STL" />
      </geometry>
      <material
        name="">
        <color
          rgba="0.89804 0.91765 0.92941 1" />
      </material>
    </visual>
    <collision>
      <origin
        xyz="0 0 0"
        rpy="0 0 0" />
      <geometry>
        <mesh
          filename="package://lmm_model/meshes/Leg_2_Link_3.STL" />
      </geometry>
    </collision>
  </link>
  <joint
    name="joint_2_3"
    type="revolute">
    <origin
      xyz="0.105 0 0"
      rpy="0 0 0" />
    <parent
      link="Leg_2_Link_2" />
    <child
      link="Leg_2_Link_3" />
    <axis
      xyz="0 1 0" />
    <limit
      lower="0"
      upper="3.1416"
      effort="3"
      velocity="5" />
  </joint>
  <link
    name="Leg_3_Link_1">
    <inertial>
      <origin
        xyz="-0.036469 0.00022501 0.0010278"
        rpy="0 0 0" />
      <mass
        value="0.12581" />
      <inertia
        ixx="6.0449E-05"
        ixy="1.6569E-06"
        ixz="-3.4003E-06"
        iyy="0.00019067"
        iyz="2.9093E-08"
        izz="0.00018671" />
    </inertial>
    <visual>
      <origin
        xyz="0 0 0"
        rpy="0 0 0" />
      <geometry>
        <mesh
          filename="package://lmm_model/meshes/Leg_3_Link_1.STL" />
      </geometry>
      <material
        name="">
        <color
          rgba="0.89804 0.91765 0.92941 1" />
      </material>
    </visual>
    <collision>
      <origin
        xyz="0 0 0"
        rpy="0 0 0" />
      <geometry>
        <mesh
          filename="package://lmm_model/meshes/Leg_3_Link_1.STL" />
      </geometry>
    </collision>
  </link>
  <joint
    name="joint_3_1"
    type="revolute">
    <origin
      xyz="-0.08 0 0.0155"
      rpy="0 0 0" />
    <parent
      link="Trunk_Body" />
    <child
      link="Leg_3_Link_1" />
    <axis
      xyz="0 0 1" />
    <limit
      lower="-1.5708"
      upper="1.5708"
      effort="3"
      velocity="5" />
  </joint>
  <link
    name="Leg_3_Link_2">
    <inertial>
      <origin
        xyz="-0.0525 0.0017906 -6.2897E-13"
        rpy="0 0 0" />
      <mass
        value="0.14442" />
      <inertia
        ixx="4.7435E-05"
        ixy="2.2281E-15"
        ixz="-3.5751E-15"
        iyy="0.00031196"
        iyz="-7.0108E-19"
        izz="0.00034589" />
    </inertial>
    <visual>
      <origin
        xyz="0 0 0"
        rpy="0 0 0" />
      <geometry>
        <mesh
          filename="package://lmm_model/meshes/Leg_3_Link_2.STL" />
      </geometry>
      <material
        name="">
        <color
          rgba="0.89804 0.91765 0.92941 1" />
      </material>
    </visual>
    <collision>
      <origin
        xyz="0 0 0"
        rpy="0 0 0" />
      <geometry>
        <mesh
          filename="package://lmm_model/meshes/Leg_3_Link_2.STL" />
      </geometry>
    </collision>
  </link>
  <joint
    name="joint_3_2"
    type="revolute">
    <origin
      xyz="-0.095 0 0"
      rpy="0 0 0" />
    <parent
      link="Leg_3_Link_1" />
    <child
      link="Leg_3_Link_2" />
    <axis
      xyz="0 1 0" />
    <limit
      lower="-1.5708"
      upper="1.5708"
      effort="3"
      velocity="5" />
  </joint>
  <link
    name="Leg_3_Link_3">
    <inertial>
      <origin
        xyz="-0.0308 1.926E-05 -3.6873E-13"
        rpy="0 0 0" />
      <mass
        value="0.055636" />
      <inertia
        ixx="2.6138E-05"
        ixy="-8.8979E-07"
        ixz="-8.3812E-16"
        iyy="7.6621E-05"
        iyz="5.6394E-15"
        izz="9.607E-05" />
    </inertial>
    <visual>
      <origin
        xyz="0 0 0"
        rpy="0 0 0" />
      <geometry>
        <mesh
          filename="package://lmm_model/meshes/Leg_3_Link_3.STL" />
      </geometry>
      <material
        name="">
        <color
          rgba="0.89804 0.91765 0.92941 1" />
      </material>
    </visual>
    <collision>
      <origin
        xyz="0 0 0"
        rpy="0 0 0" />
      <geometry>
        <mesh
          filename="package://lmm_model/meshes/Leg_3_Link_3.STL" />
      </geometry>
    </collision>
  </link>
  <joint
    name="joint_3_3"
    type="revolute">
    <origin
      xyz="-0.105 0 0"
      rpy="0 0 0" />
    <parent
      link="Leg_3_Link_2" />
    <child
      link="Leg_3_Link_3" />
    <axis
      xyz="0 1 0" />
    <limit
      lower="-3.1416"
      upper="0"
      effort="3"
      velocity="5" />
  </joint>
  <link
    name="Leg_4_Link_1">
    <inertial>
      <origin
        xyz="0.036469 0.00022501 0.0010278"
        rpy="0 0 0" />
      <mass
        value="0.12581" />
      <inertia
        ixx="6.0449E-05"
        ixy="-1.6569E-06"
        ixz="3.4003E-06"
        iyy="0.00019067"
        iyz="2.9093E-08"
        izz="0.00018671" />
    </inertial>
    <visual>
      <origin
        xyz="0 0 0"
        rpy="0 0 0" />
      <geometry>
        <mesh
          filename="package://lmm_model/meshes/Leg_4_Link_1.STL" />
      </geometry>
      <material
        name="">
        <color
          rgba="0.89804 0.91765 0.92941 1" />
      </material>
    </visual>
    <collision>
      <origin
        xyz="0 0 0"
        rpy="0 0 0" />
      <geometry>
        <mesh
          filename="package://lmm_model/meshes/Leg_4_Link_1.STL" />
      </geometry>
    </collision>
  </link>
  <joint
    name="joint_4_1"
    type="revolute">
    <origin
      xyz="0.08 0 0.0155"
      rpy="0 0 0" />
    <parent
      link="Trunk_Body" />
    <child
      link="Leg_4_Link_1" />
    <axis
      xyz="0 0 1" />
    <limit
      lower="-1.5708"
      upper="1.5708"
      effort="3"
      velocity="5" />
  </joint>
  <link
    name="Leg_4_Link_2">
    <inertial>
      <origin
        xyz="0.0525 0.0017906 6.2925E-13"
        rpy="0 0 0" />
      <mass
        value="0.14442" />
      <inertia
        ixx="4.7435E-05"
        ixy="2.2342E-15"
        ixz="-3.5773E-15"
        iyy="0.00031196"
        iyz="1.5029E-18"
        izz="0.00034589" />
    </inertial>
    <visual>
      <origin
        xyz="0 0 0"
        rpy="0 0 0" />
      <geometry>
        <mesh
          filename="package://lmm_model/meshes/Leg_4_Link_2.STL" />
      </geometry>
      <material
        name="">
        <color
          rgba="0.89804 0.91765 0.92941 1" />
      </material>
    </visual>
    <collision>
      <origin
        xyz="0 0 0"
        rpy="0 0 0" />
      <geometry>
        <mesh
          filename="package://lmm_model/meshes/Leg_4_Link_2.STL" />
      </geometry>
    </collision>
  </link>
  <joint
    name="joint_4_2"
    type="revolute">
    <origin
      xyz="0.095 0 0"
      rpy="0 0 0" />
    <parent
      link="Leg_4_Link_1" />
    <child
      link="Leg_4_Link_2" />
    <axis
      xyz="0 1 0" />
    <limit
      lower="-1.5708"
      upper="1.5708"
      effort="3"
      velocity="5" />
  </joint>
  <link
    name="Leg_4_Link_3">
    <inertial>
      <origin
        xyz="0.0308 1.926E-05 3.6884E-13"
        rpy="0 0 0" />
      <mass
        value="0.055636" />
      <inertia
        ixx="2.6138E-05"
        ixy="8.8979E-07"
        ixz="-8.3861E-16"
        iyy="7.6621E-05"
        iyz="-5.6389E-15"
        izz="9.607E-05" />
    </inertial>
    <visual>
      <origin
        xyz="0 0 0"
        rpy="0 0 0" />
      <geometry>
        <mesh
          filename="package://lmm_model/meshes/Leg_4_Link_3.STL" />
      </geometry>
      <material
        name="">
        <color
          rgba="0.89804 0.91765 0.92941 1" />
      </material>
    </visual>
    <collision>
      <origin
        xyz="0 0 0"
        rpy="0 0 0" />
      <geometry>
        <mesh
          filename="package://lmm_model/meshes/Leg_4_Link_3.STL" />
      </geometry>
    </collision>
  </link>
  <joint
    name="joint_4_3"
    type="revolute">
    <origin
      xyz="0.105 0 0"
      rpy="0 0 0" />
    <parent
      link="Leg_4_Link_2" />
    <child
      link="Leg_4_Link_3" />
    <axis
      xyz="0 1 0" />
    <limit
      lower="0"
      upper="3.1416"
      effort="3"
      velocity="5" />
  </joint>
  <link
    name="Leg_5_Link_1">
    <inertial>
      <origin
        xyz="-0.036469 0.00022501 0.0010278"
        rpy="0 0 0" />
      <mass
        value="0.12581" />
      <inertia
        ixx="6.0449E-05"
        ixy="1.6569E-06"
        ixz="-3.4003E-06"
        iyy="0.00019067"
        iyz="2.9093E-08"
        izz="0.00018671" />
    </inertial>
    <visual>
      <origin
        xyz="0 0 0"
        rpy="0 0 0" />
      <geometry>
        <mesh
          filename="package://lmm_model/meshes/Leg_5_Link_1.STL" />
      </geometry>
      <material
        name="">
        <color
          rgba="0.89804 0.91765 0.92941 1" />
      </material>
    </visual>
    <collision>
      <origin
        xyz="0 0 0"
        rpy="0 0 0" />
      <geometry>
        <mesh
          filename="package://lmm_model/meshes/Leg_5_Link_1.STL" />
      </geometry>
    </collision>
  </link>
  <joint
    name="joint_5_1"
    type="revolute">
    <origin
      xyz="-0.08 -0.205 0.0155"
      rpy="0 0 0" />
    <parent
      link="Trunk_Body" />
    <child
      link="Leg_5_Link_1" />
    <axis
      xyz="0 0 1" />
    <limit
      lower="-1.5708"
      upper="1.5708"
      effort="3"
      velocity="5" />
  </joint>
  <link
    name="Leg_5_Link_2">
    <inertial>
      <origin
        xyz="-0.0525 0.0017906 -6.2894E-13"
        rpy="0 0 0" />
      <mass
        value="0.14442" />
      <inertia
        ixx="4.7435E-05"
        ixy="2.2281E-15"
        ixz="-3.5752E-15"
        iyy="0.00031196"
        iyz="-7.0353E-19"
        izz="0.00034589" />
    </inertial>
    <visual>
      <origin
        xyz="0 0 0"
        rpy="0 0 0" />
      <geometry>
        <mesh
          filename="package://lmm_model/meshes/Leg_5_Link_2.STL" />
      </geometry>
      <material
        name="">
        <color
          rgba="0.89804 0.91765 0.92941 1" />
      </material>
    </visual>
    <collision>
      <origin
        xyz="0 0 0"
        rpy="0 0 0" />
      <geometry>
        <mesh
          filename="package://lmm_model/meshes/Leg_5_Link_2.STL" />
      </geometry>
    </collision>
  </link>
  <joint
    name="joint_5_2"
    type="revolute">
    <origin
      xyz="-0.095 0 0"
      rpy="0 0 0" />
    <parent
      link="Leg_5_Link_1" />
    <child
      link="Leg_5_Link_2" />
    <axis
      xyz="0 1 0" />
    <limit
      lower="-1.5708"
      upper="1.5708"
      effort="3"
      velocity="5" />
  </joint>
  <link
    name="Leg_5_Link_3">
    <inertial>
      <origin
        xyz="-0.0308 1.926E-05 -3.6873E-13"
        rpy="0 0 0" />
      <mass
        value="0.055636" />
      <inertia
        ixx="2.6138E-05"
        ixy="-8.8979E-07"
        ixz="-8.3812E-16"
        iyy="7.6621E-05"
        iyz="5.6394E-15"
        izz="9.607E-05" />
    </inertial>
    <visual>
      <origin
        xyz="0 0 0"
        rpy="0 0 0" />
      <geometry>
        <mesh
          filename="package://lmm_model/meshes/Leg_5_Link_3.STL" />
      </geometry>
      <material
        name="">
        <color
          rgba="0.89804 0.91765 0.92941 1" />
      </material>
    </visual>
    <collision>
      <origin
        xyz="0 0 0"
        rpy="0 0 0" />
      <geometry>
        <mesh
          filename="package://lmm_model/meshes/Leg_5_Link_3.STL" />
      </geometry>
    </collision>
  </link>
  <joint
    name="joint_5_3"
    type="revolute">
    <origin
      xyz="-0.105 0 0"
      rpy="0 0 0" />
    <parent
      link="Leg_5_Link_2" />
    <child
      link="Leg_5_Link_3" />
    <axis
      xyz="0 1 0" />
    <limit
      lower="-3.1416"
      upper="0"
      effort="3"
      velocity="5" />
  </joint>
  <link
    name="Leg_6_Link_1">
    <inertial>
      <origin
        xyz="0.036469 0.00022501 0.0010278"
        rpy="0 0 0" />
      <mass
        value="0.12581" />
      <inertia
        ixx="6.0449E-05"
        ixy="-1.6569E-06"
        ixz="3.4003E-06"
        iyy="0.00019067"
        iyz="2.9093E-08"
        izz="0.00018671" />
    </inertial>
    <visual>
      <origin
        xyz="0 0 0"
        rpy="0 0 0" />
      <geometry>
        <mesh
          filename="package://lmm_model/meshes/Leg_6_Link_1.STL" />
      </geometry>
      <material
        name="">
        <color
          rgba="0.89804 0.91765 0.92941 1" />
      </material>
    </visual>
    <collision>
      <origin
        xyz="0 0 0"
        rpy="0 0 0" />
      <geometry>
        <mesh
          filename="package://lmm_model/meshes/Leg_6_Link_1.STL" />
      </geometry>
    </collision>
  </link>
  <joint
    name="joint_6_1"
    type="revolute">
    <origin
      xyz="0.08 -0.205 0.0155"
      rpy="0 0 0" />
    <parent
      link="Trunk_Body" />
    <child
      link="Leg_6_Link_1" />
    <axis
      xyz="0 0 1" />
    <limit
      lower="-1.5708"
      upper="1.5708"
      effort="3"
      velocity="5" />
  </joint>
  <link
    name="Leg_6_Link_2">
    <inertial>
      <origin
        xyz="0.0525 0.0017906 6.2927E-13"
        rpy="0 0 0" />
      <mass
        value="0.14442" />
      <inertia
        ixx="4.7435E-05"
        ixy="2.2341E-15"
        ixz="-3.5772E-15"
        iyy="0.00031196"
        iyz="1.5358E-18"
        izz="0.00034589" />
    </inertial>
    <visual>
      <origin
        xyz="0 0 0"
        rpy="0 0 0" />
      <geometry>
        <mesh
          filename="package://lmm_model/meshes/Leg_6_Link_2.STL" />
      </geometry>
      <material
        name="">
        <color
          rgba="0.89804 0.91765 0.92941 1" />
      </material>
    </visual>
    <collision>
      <origin
        xyz="0 0 0"
        rpy="0 0 0" />
      <geometry>
        <mesh
          filename="package://lmm_model/meshes/Leg_6_Link_2.STL" />
      </geometry>
    </collision>
  </link>
  <joint
    name="joint_6_2"
    type="revolute">
    <origin
      xyz="0.095 0 0"
      rpy="0 0 0" />
    <parent
      link="Leg_6_Link_1" />
    <child
      link="Leg_6_Link_2" />
    <axis
      xyz="0 1 0" />
    <limit
      lower="-1.5708"
      upper="1.5708"
      effort="3"
      velocity="5" />
  </joint>
  <link
    name="Leg_6_Link_3">
    <inertial>
      <origin
        xyz="0.0308 1.926E-05 3.6893E-13"
        rpy="0 0 0" />
      <mass
        value="0.055636" />
      <inertia
        ixx="2.6138E-05"
        ixy="8.8979E-07"
        ixz="-8.3859E-16"
        iyy="7.6621E-05"
        iyz="-5.6389E-15"
        izz="9.607E-05" />
    </inertial>
    <visual>
      <origin
        xyz="0 0 0"
        rpy="0 0 0" />
      <geometry>
        <mesh
          filename="package://lmm_model/meshes/Leg_6_Link_3.STL" />
      </geometry>
      <material
        name="">
        <color
          rgba="0.89804 0.91765 0.92941 1" />
      </material>
    </visual>
    <collision>
      <origin
        xyz="0 0 0"
        rpy="0 0 0" />
      <geometry>
        <mesh
          filename="package://lmm_model/meshes/Leg_6_Link_3.STL" />
      </geometry>
    </collision>
  </link>
  <joint
    name="joint_6_3"
    type="revolute">
    <origin
      xyz="0.105 0 0"
      rpy="0 0 0" />
    <parent
      link="Leg_6_Link_2" />
    <child
      link="Leg_6_Link_3" />
    <axis
      xyz="0 1 0" />
    <limit
      lower="0"
      upper="3.1416"
      effort="3"
      velocity="5" />
  </joint>
  <link
    name="M_Link_1">
    <inertial>
      <origin
        xyz="0.00055034 3.8891E-13 0.01547"
        rpy="0 0 0" />
      <mass
        value="0.051436" />
      <inertia
        ixx="2.759E-05"
        ixy="9.2369E-12"
        ixz="-6.8023E-07"
        iyy="4.2613E-05"
        iyz="-4.8064E-16"
        izz="4.2594E-05" />
    </inertial>
    <visual>
      <origin
        xyz="0 0 0"
        rpy="0 0 0" />
      <geometry>
        <mesh
          filename="package://lmm_model/meshes/M_Link_1.STL" />
      </geometry>
      <material
        name="">
        <color
          rgba="0.89804 0.91765 0.92941 1" />
      </material>
    </visual>
    <collision>
      <origin
        xyz="0 0 0"
        rpy="0 0 0" />
      <geometry>
        <mesh
          filename="package://lmm_model/meshes/M_Link_1.STL" />
      </geometry>
    </collision>
  </link>
  <joint
    name="joint_m_1"
    type="revolute">
    <origin
      xyz="0 0.1025 0.0445"
      rpy="0 0 0" />
    <parent
      link="Trunk_Body" />
    <child
      link="M_Link_1" />
    <axis
      xyz="0 0 1" />
    <limit
      lower="-1.5708"
      upper="1.5708"
      effort="3"
      velocity="5" />
  </joint>
  <link
    name="M_Link_2">
    <inertial>
      <origin
        xyz="0.0011652 8.1768E-13 0.125"
        rpy="0 0 0" />
      <mass
        value="0.22192" />
      <inertia
        ixx="0.0022264"
        ixy="-4.5276E-14"
        ixz="4.4278E-17"
        iyy="0.0022904"
        iyz="5.0702E-17"
        izz="0.00010329" />
    </inertial>
    <visual>
      <origin
        xyz="0 0 0"
        rpy="0 0 0" />
      <geometry>
        <mesh
          filename="package://lmm_model/meshes/M_Link_2.STL" />
      </geometry>
      <material
        name="">
        <color
          rgba="0.89804 0.91765 0.92941 1" />
      </material>
    </visual>
    <collision>
      <origin
        xyz="0 0 0"
        rpy="0 0 0" />
      <geometry>
        <mesh
          filename="package://lmm_model/meshes/M_Link_2.STL" />
      </geometry>
    </collision>
  </link>
  <joint
    name="joint_m_2"
    type="revolute">
    <origin
      xyz="0 0 0.0395"
      rpy="0 0 0" />
    <parent
      link="M_Link_1" />
    <child
      link="M_Link_2" />
    <axis
      xyz="1 0 0" />
    <limit
      lower="-1.5708"
      upper="1.5708"
      effort="3"
      velocity="5" />
  </joint>
  <link
    name="M_Link_3">
    <inertial>
      <origin
        xyz="-4.211E-05 -1.2356E-08 0.10228"
        rpy="0 0 0" />
      <mass
        value="0.13111" />
      <inertia
        ixx="0.00059577"
        ixy="1.2916E-12"
        ixz="6.0949E-06"
        iyy="0.00066378"
        iyz="1.255E-10"
        izz="0.00010414" />
    </inertial>
    <visual>
      <origin
        xyz="0 0 0"
        rpy="0 0 0" />
      <geometry>
        <mesh
          filename="package://lmm_model/meshes/M_Link_3.STL" />
      </geometry>
      <material
        name="">
        <color
          rgba="0.89804 0.91765 0.92941 1" />
      </material>
    </visual>
    <collision>
      <origin
        xyz="0 0 0"
        rpy="0 0 0" />
      <geometry>
        <mesh
          filename="package://lmm_model/meshes/M_Link_3.STL" />
      </geometry>
    </collision>
  </link>
  <joint
    name="joint_m_3"
    type="revolute">
    <origin
      xyz="0 0 0.25"
      rpy="0 0 0" />
    <parent
      link="M_Link_2" />
    <child
      link="M_Link_3" />
    <axis
      xyz="1 0 0" />
    <limit
      lower="-1.5708"
      upper="1.5708"
      effort="3"
      velocity="5" />
  </joint>
  <link
    name="Gripper">
    <inertial>
      <origin
        xyz="0.00087814 0.0018495 0.047514"
        rpy="0 0 0" />
      <mass
        value="0.03755" />
      <inertia
        ixx="1.4446E-05"
        ixy="-3.8029E-07"
        ixz="3.3319E-07"
        iyy="1.8014E-05"
        iyz="7.3875E-07"
        izz="6.9979E-06" />
    </inertial>
    <visual>
      <origin
        xyz="0 0 0"
        rpy="0 0 0" />
      <geometry>
        <mesh
          filename="package://lmm_model/meshes/Gripper.STL" />
      </geometry>
      <material
        name="">
        <color
          rgba="1 1 1 1" />
      </material>
    </visual>
    <collision>
      <origin
        xyz="0 0 0"
        rpy="0 0 0" />
      <geometry>
        <mesh
          filename="package://lmm_model/meshes/Gripper.STL" />
      </geometry>
    </collision>
  </link>
  <joint
    name="joint_m_4"
    type="revolute">
    <origin
      xyz="0 0 0.2"
      rpy="0 0 0" />
    <parent
      link="M_Link_3" />
    <child
      link="Gripper" />
    <axis
      xyz="0 0 1" />
    <limit
      lower="-1.5708"
      upper="1.5708"
      effort="3"
      velocity="5" />
  </joint>

  <!-- GAZEBO PART -->

  <!-- Gazebo ROS Control -->
  <gazebo>
    <plugin name="gazebo_ros_control" filename="libgazebo_ros_control.so">
      <robotNamespace>/lmm</robotNamespace>
      <robotSimType>gazebo_ros_control/DefaultRobotHWSim</robotSimType>
      <legacyModeNS>true</legacyModeNS>
    </plugin>
    <material>Gazebo/DarkGrey</material>
  </gazebo>
  <gazebo reference="Leg_1_Link_3">
    <mu1>5</mu1>
    <mu2>5</mu2>
    <!-- <material>Gazebo/Orange</material> -->
  </gazebo>
  <gazebo reference="Leg_2_Link_3">
    <mu1>5</mu1>
    <mu2>5</mu2>
    <!-- <material>Gazebo/Orange</material> -->
  </gazebo>
  <gazebo reference="Leg_3_Link_3">
    <mu1>5</mu1>
    <mu2>5</mu2>
    <!-- <material>Gazebo/Orange</material> -->
  </gazebo>
  <gazebo reference="Leg_4_Link_3">
    <mu1>5</mu1>
    <mu2>5</mu2>
    <!-- <material>Gazebo/Orange</material> -->
  </gazebo>
  <gazebo reference="Leg_5_Link_3">
    <mu1>5</mu1>
    <mu2>5</mu2>
    <!-- <material>Gazebo/Orange</material> -->
  </gazebo>
  <gazebo reference="Leg_6_Link_3">
    <mu1>5</mu1>
    <mu2>5</mu2>
    <!-- <material>Gazebo/Orange</material> -->
  </gazebo>

  <!-- Transmission -->
  <transmission name="joint_1_1_trans">
    <type>transmission_interface/SimpleTransmission</type>
    <joint name="joint_1_1">
      <hardwareInterface>hardware_interface/EffortJointInterface</hardwareInterface>
    </joint>
    <actuator name="motor_1_1">
      <hardwareInterface>hardware_interface/EffortJointInterface</hardwareInterface>
      <mechanicalReduction>1</mechanicalReduction>
    </actuator>
  </transmission>
  <transmission name="joint_1_2_trans">
    <type>transmission_interface/SimpleTransmission</type>
    <joint name="joint_1_2">
      <hardwareInterface>hardware_interface/EffortJointInterface</hardwareInterface>
    </joint>
    <actuator name="motor_1_2">
      <hardwareInterface>hardware_interface/EffortJointInterface</hardwareInterface>
      <mechanicalReduction>1</mechanicalReduction>
    </actuator>
  </transmission>
  <transmission name="joint_1_3_trans">
    <type>transmission_interface/SimpleTransmission</type>
    <joint name="joint_1_3">
      <hardwareInterface>hardware_interface/EffortJointInterface</hardwareInterface>
    </joint>
    <actuator name="motor_1_3">
      <hardwareInterface>hardware_interface/EffortJointInterface</hardwareInterface>
      <mechanicalReduction>1</mechanicalReduction>
    </actuator>
  </transmission>
  <transmission name="joint_2_1_trans">
    <type>transmission_interface/SimpleTransmission</type>
    <joint name="joint_2_1">
      <hardwareInterface>hardware_interface/EffortJointInterface</hardwareInterface>
    </joint>
    <actuator name="motor_2_1">
      <hardwareInterface>hardware_interface/EffortJointInterface</hardwareInterface>
      <mechanicalReduction>1</mechanicalReduction>
    </actuator>
  </transmission>
  <transmission name="joint_2_2_trans">
    <type>transmission_interface/SimpleTransmission</type>
    <joint name="joint_2_2">
      <hardwareInterface>hardware_interface/EffortJointInterface</hardwareInterface>
    </joint>
    <actuator name="motor_2_2">
      <hardwareInterface>hardware_interface/EffortJointInterface</hardwareInterface>
      <mechanicalReduction>1</mechanicalReduction>
    </actuator>
  </transmission>
  <transmission name="joint_2_3_trans">
    <type>transmission_interface/SimpleTransmission</type>
    <joint name="joint_2_3">
      <hardwareInterface>hardware_interface/EffortJointInterface</hardwareInterface>
    </joint>
    <actuator name="motor_2_3">
      <hardwareInterface>hardware_interface/EffortJointInterface</hardwareInterface>
      <mechanicalReduction>1</mechanicalReduction>
    </actuator>
  </transmission>
  <transmission name="joint_3_1_trans">
    <type>transmission_interface/SimpleTransmission</type>
    <joint name="joint_3_1">
      <hardwareInterface>hardware_interface/EffortJointInterface</hardwareInterface>
    </joint>
    <actuator name="motor_3_1">
      <hardwareInterface>hardware_interface/EffortJointInterface</hardwareInterface>
      <mechanicalReduction>1</mechanicalReduction>
    </actuator>
  </transmission>
  <transmission name="joint_3_2_trans">
    <type>transmission_interface/SimpleTransmission</type>
    <joint name="joint_3_2">
      <hardwareInterface>hardware_interface/EffortJointInterface</hardwareInterface>
    </joint>
    <actuator name="motor_3_2">
      <hardwareInterface>hardware_interface/EffortJointInterface</hardwareInterface>
      <mechanicalReduction>1</mechanicalReduction>
    </actuator>
  </transmission>
  <transmission name="joint_3_3_trans">
    <type>transmission_interface/SimpleTransmission</type>
    <joint name="joint_3_3">
      <hardwareInterface>hardware_interface/EffortJointInterface</hardwareInterface>
    </joint>
    <actuator name="motor_3_3">
      <hardwareInterface>hardware_interface/EffortJointInterface</hardwareInterface>
      <mechanicalReduction>1</mechanicalReduction>
    </actuator>
  </transmission>
  <transmission name="joint_4_1_trans">
    <type>transmission_interface/SimpleTransmission</type>
    <joint name="joint_4_1">
      <hardwareInterface>hardware_interface/EffortJointInterface</hardwareInterface>
    </joint>
    <actuator name="motor_4_1">
      <hardwareInterface>hardware_interface/EffortJointInterface</hardwareInterface>
      <mechanicalReduction>1</mechanicalReduction>
    </actuator>
  </transmission>
  <transmission name="joint_4_2_trans">
    <type>transmission_interface/SimpleTransmission</type>
    <joint name="joint_4_2">
      <hardwareInterface>hardware_interface/EffortJointInterface</hardwareInterface>
    </joint>
    <actuator name="motor_4_2">
      <hardwareInterface>hardware_interface/EffortJointInterface</hardwareInterface>
      <mechanicalReduction>1</mechanicalReduction>
    </actuator>
  </transmission>
  <transmission name="joint_4_3_trans">
    <type>transmission_interface/SimpleTransmission</type>
    <joint name="joint_4_3">
      <hardwareInterface>hardware_interface/EffortJointInterface</hardwareInterface>
    </joint>
    <actuator name="motor_4_3">
      <hardwareInterface>hardware_interface/EffortJointInterface</hardwareInterface>
      <mechanicalReduction>1</mechanicalReduction>
    </actuator>
  </transmission>
  <transmission name="joint_5_1_trans">
    <type>transmission_interface/SimpleTransmission</type>
    <joint name="joint_5_1">
      <hardwareInterface>hardware_interface/EffortJointInterface</hardwareInterface>
    </joint>
    <actuator name="motor_5_1">
      <hardwareInterface>hardware_interface/EffortJointInterface</hardwareInterface>
      <mechanicalReduction>1</mechanicalReduction>
    </actuator>
  </transmission>
  <transmission name="joint_5_2_trans">
    <type>transmission_interface/SimpleTransmission</type>
    <joint name="joint_5_2">
      <hardwareInterface>hardware_interface/EffortJointInterface</hardwareInterface>
    </joint>
    <actuator name="motor_5_2">
      <hardwareInterface>hardware_interface/EffortJointInterface</hardwareInterface>
      <mechanicalReduction>1</mechanicalReduction>
    </actuator>
  </transmission>
  <transmission name="joint_5_3_trans">
    <type>transmission_interface/SimpleTransmission</type>
    <joint name="joint_5_3">
      <hardwareInterface>hardware_interface/EffortJointInterface</hardwareInterface>
    </joint>
    <actuator name="motor_5_3">
      <hardwareInterface>hardware_interface/EffortJointInterface</hardwareInterface>
      <mechanicalReduction>1</mechanicalReduction>
    </actuator>
  </transmission>
  <transmission name="joint_6_1_trans">
    <type>transmission_interface/SimpleTransmission</type>
    <joint name="joint_6_1">
      <hardwareInterface>hardware_interface/EffortJointInterface</hardwareInterface>
    </joint>
    <actuator name="motor_6_1">
      <hardwareInterface>hardware_interface/EffortJointInterface</hardwareInterface>
      <mechanicalReduction>1</mechanicalReduction>
    </actuator>
  </transmission>
  <transmission name="joint_6_2_trans">
    <type>transmission_interface/SimpleTransmission</type>
    <joint name="joint_6_2">
      <hardwareInterface>hardware_interface/EffortJointInterface</hardwareInterface>
    </joint>
    <actuator name="motor_6_2">
      <hardwareInterface>hardware_interface/EffortJointInterface</hardwareInterface>
      <mechanicalReduction>1</mechanicalReduction>
    </actuator>
  </transmission>
  <transmission name="joint_6_3_trans">
    <type>transmission_interface/SimpleTransmission</type>
    <joint name="joint_6_3">
      <hardwareInterface>hardware_interface/EffortJointInterface</hardwareInterface>
    </joint>
    <actuator name="motor_6_3">
      <hardwareInterface>hardware_interface/EffortJointInterface</hardwareInterface>
      <mechanicalReduction>1</mechanicalReduction>
    </actuator>
  </transmission>
  <transmission name="joint_m_1_trans">
    <type>transmission_interface/SimpleTransmission</type>
    <joint name="joint_m_1">
      <hardwareInterface>hardware_interface/EffortJointInterface</hardwareInterface>
    </joint>
    <actuator name="motor_m_1">
      <hardwareInterface>hardware_interface/EffortJointInterface</hardwareInterface>
      <mechanicalReduction>1</mechanicalReduction>
    </actuator>
  </transmission>
  <transmission name="joint_m_2_trans">
    <type>transmission_interface/SimpleTransmission</type>
    <joint name="joint_m_2">
      <hardwareInterface>hardware_interface/EffortJointInterface</hardwareInterface>
    </joint>
    <actuator name="motor_m_2">
      <hardwareInterface>hardware_interface/EffortJointInterface</hardwareInterface>
      <mechanicalReduction>1</mechanicalReduction>
    </actuator>
  </transmission>
  <transmission name="joint_m_3_trans">
    <type>transmission_interface/SimpleTransmission</type>
    <joint name="joint_m_3">
      <hardwareInterface>hardware_interface/EffortJointInterface</hardwareInterface>
    </joint>
    <actuator name="motor_m_3">
      <hardwareInterface>hardware_interface/EffortJointInterface</hardwareInterface>
      <mechanicalReduction>1</mechanicalReduction>
    </actuator>
  </transmission>
  <transmission name="joint_m_4_trans">
    <type>transmission_interface/SimpleTransmission</type>
    <joint name="joint_m_4">
      <hardwareInterface>hardware_interface/EffortJointInterface</hardwareInterface>
    </joint>
    <actuator name="motor_m_4">
      <hardwareInterface>hardware_interface/EffortJointInterface</hardwareInterface>
      <mechanicalReduction>1</mechanicalReduction>
    </actuator>
  </transmission>

</robot>
